Workbook

Sheet Method & Notes
B1: IDP Vendor Cost Model — LlamaExtract · Reducto · Extend
B3: Purpose: reproduce, as live formulas, the cost estimates in the vendor-research doc for DEC-01 / D-a1.
B4: Companion to: 00_Internal_Work/IDP/2026-07-21 Vendor research — LlamaExtract, Reducto, Extend.md
B6: HOW TO READ THIS WORKBOOK
B7: • Yellow cells = editable assumptions (rates, volumes, modes). Change these.
B8: • Green cells = formulas / derived values. Do not hand-edit; they recompute.
B9: • Sheets: Assumptions (inputs) → Cost per page (by mode) → Scenarios (totals).
B11: THE CORE FORMULA
B12: $ per page = ( Σ credits/page for each operation in the pipeline ) × ( $ per credit at your plan tier )
B13: Total $ = $ per page × total pages
B15: WHAT A 'PIPELINE' IS (why extract is never just 'extract')
B16: A schema extraction is a chain: Parse (read the doc) → Extract (fill the schema) → optionally
... B39: Source: each rate is from the vendor's public pricing/credit docs, fetched 2026-07-21. Vendor-reported, list rates.

Sheet Assumptions
A1: Assumptions & Rate Cards
A2: Yellow = editable input. Credits per page unless noted. List rates, self-serve tiers, pre-discount.
A4: PRICE PER CREDIT (USD)
A5: Reducto (Standard, after 15k free) | B5: 0.015 | C5: reducto.ai/pricing
A6: LlamaCloud (NA/EU, 1,000 cr = $1.25) | B6: 0.00125 | C6: developers.llamaindex.ai/.../pricing
A7: Extend — Pay-As-You-Go | B7: 0.0125 | C7: derived: Parse 2cr = $0.025
A8: Extend — Scale ($500/mo, 50k cr incl.) | B8: 0.01 | C8: derived: Parse 2cr = $0.02
A10: SCENARIO VOLUMES
A11: PoC — pages per document | B11: 3 | C11: e.g. a bill of lading
A12: PoC — number of documents | B12: 50 | C12: the ≥50-doc batch
A13: Production — pages per month | B13: 10000 | C13: illustrative volume
A14: Deep Extract — fields per document | B14: 12 | C14: for Reducto Deep Extract calc
A16: REDUCTO — credits/page
A17: Parse — standard | B17: 1
A18: Parse — complex page | B18: 2 | C18: tables / merged cells / KV regions
A19: Parse — agentic (mid of 2–4) | B19: 3
A20: Extract — standard | B20: 2
A21: Deep Extract — per page | B21: 4 | C21: agentic mode
A22: Deep Extract — per field | B22: 0.1
A23: Deep Extract — minimum per DOC | B23: 30 | C23: floor dominates short docs
A24: Multiplier — optimize_for_latency | B24: 2
A25: Multiplier — batch queue (−20%) | B25: 0.8
A27: LLAMACLOUD — credits/page
A28: Extract tier — Cost-effective | B28: 5
A29: Extract tier — Agentic | B29: 15
A30: Parse tier — Fast | B30: 1
A31: Parse tier — Cost-effective | B31: 3
A32: Parse tier — Agentic | B32: 10
A33: Parse tier — Agentic Plus | B33: 45
A34: Classify — fast | B34: 1
A35: Split — default | B35: 4
A37: EXTEND — credits/page
A38: Parse — performance | B38: 2
A39: Parse — light (~4× cheaper) | B39: 0.5
A40: Extract — performance | B40: 3
A41: Extract — light | B41: 0.75
A42: Classify | B42: 1
A43: Split | B43: 2
A44: Review Agent (HITL) — add/page | B44: 1
A45: Agentic OCR correction — add/page | B45: 1
...

Sheet Cost per page
A1: Cost per page — by mode
A2: Credits/page and $/page are formulas referencing the Assumptions sheet.
A4: Vendor | B4: Mode / pipeline | C4: Credits/page | D4: $ per credit | E4: $ per page
A5: LlamaCloud | B5: Cost-effective extract + Fast parse (cheapest) | C5: =Assumptions!B28+Assumptions!B30 | D5: =Assumptions!B6 | E5: =C5*D5
A6: LlamaCloud | B6: Cost-effective extract + Cost-effective parse | C6: =Assumptions!B28+Assumptions!B31 | D6: =Assumptions!B6 | E6: =C6*D6
A7: LlamaCloud | B7: Agentic extract + Agentic parse (mid/quality) | C7: =Assumptions!B29+Assumptions!B32 | D7: =Assumptions!B6 | E7: =C7*D7
A8: LlamaCloud | B8: Agentic extract + Agentic Plus parse (max) | C8: =Assumptions!B29+Assumptions!B33 | D8: =Assumptions!B6 | E8: =C8*D8
A9: LlamaCloud | B9: Extract-only (cached re-run, cost-effective) | C9: =Assumptions!B28 | D9: =Assumptions!B6 | E9: =C9*D9
A10: Reducto | B10: Standard parse + standard extract (cheapest) | C10: =Assumptions!B17+Assumptions!B20 | D10: =Assumptions!B5 | E10: =C10*D10
A11: Reducto | B11: Complex-page parse + extract | C11: =Assumptions!B18+Assumptions!B20 | D11: =Assumptions!B5 | E11: =C11*D11
A12: Reducto | B12: Agentic parse + extract | C12: =Assumptions!B19+Assumptions!B20 | D12: =Assumptions!B5 | E12: =C12*D12
A13: Reducto | B13: Extract-only on cached jobid:// (no re-parse) | C13: =Assumptions!B20 | D13: =Assumptions!B5 | E13: =C13*D13
A14: Extend | B14: Parse + Extract (performance, PAYG) | C14: =Assumptions!B38+Assumptions!B40 | D14: =Assumptions!B7 | E14: =C14*D14
A15: Extend | B15: Parse + Extract (performance, Scale) | C15: =Assumptions!B38+Assumptions!B40 | D15: =Assumptions!B8 | E15: =C15*D15
A16: Extend | B16: Light mode (parse + extract, PAYG) | C16: =Assumptions!B39+Assumptions!B41 | D16: =Assumptions!B7 | E16: =C16*D16
A17: Extend | B17: Perf + Review Agent HITL (PAYG) | C17: =Assumptions!B38+Assumptions!B40+Assumptions!B44 | D17: =Assumptions!B7 | E17: =C17*D17

Sheet Scenarios
A1: Scenarios — total cost
A2: Total pages, base/add-on credits, $/page and Total $ are formulas. Change modes on the Assumptions sheet.
A4: Scenario | B4: Vendor / tier | C4: Mode / pipeline | D4: $ per credit | E4: Total pages | F4: Base cr/page | G4: Add-on cr/page | H4: $ per page | I4: Total $
A5: PoC · LlamaCloud · cheapest | B5: LlamaCloud | C5: Cost-eff extract + Fast parse | D5: =Assumptions!B6 | E5: =Assumptions!B11*Assumptions!B12 | F5: =Assumptions!B28+Assumptions!B30 | G5: 0 | H5: =(F5+G5)*D5 | I5: =H5*E5
A6: PoC · Reducto · standard | B6: Reducto Standard | C6: Std parse + std extract | D6: =Assumptions!B5 | E6: =Assumptions!B11*Assumptions!B12 | F6: =Assumptions!B17+Assumptions!B20 | G6: 0 | H6: =(F6+G6)*D6 | I6: =H6*E6
A7: PoC · Extend · performance | B7: Extend PAYG | C7: Parse + Extract (perf) | D7: =Assumptions!B7 | E7: =Assumptions!B11*Assumptions!B12 | F7: =Assumptions!B38+Assumptions!B40 | G7: 0 | H7: =(F7+G7)*D7 | I7: =H7*E7
A8: PoC · Extend · perf + Review Agent | B8: Extend PAYG | C8: Parse + Extract + HITL | D8: =Assumptions!B7 | E8: =Assumptions!B11*Assumptions!B12 | F8: =Assumptions!B38+Assumptions!B40 | G8: =Assumptions!B44 | H8: =(F8+G8)*D8 | I8: =H8*E8
A10: Prod · LlamaCloud · agentic | B10: LlamaCloud | C10: Agentic extract + Agentic parse | D10: =Assumptions!B6 | E10: =Assumptions!B13 | F10: =Assumptions!B29+Assumptions!B32 | G10: 0 | H10: =(F10+G10)*D10 | I10: =H10*E10
A11: Prod · Reducto · complex | B11: Reducto Standard | C11: Complex parse + extract | D11: =Assumptions!B5 | E11: =Assumptions!B13 | F11: =Assumptions!B18+Assumptions!B20 | G11: 0 | H11: =(F11+G11)*D11 | I11: =H11*E11
A12: Prod · Extend · perf + Review (Scale) | B12: Extend Scale | C12: Parse + Extract + HITL | D12: =Assumptions!B8 | E12: =Assumptions!B13 | F12: =Assumptions!B38+Assumptions!B40 | G12: =Assumptions!B44 | H12: =(F12+G12)*D12 | I12: =H12*E12
A14: Reducto Deep Extract — per-doc minimum mechanic
A15: Pages per document | B15: =Assumptions!B11
A16: Fields per document | B16: =Assumptions!B14
A17: Number of documents | B17: =Assumptions!B12
A18: Raw credits/doc = 4×pages + 0.1×fields + 1×pages (parse) | B18: =Assumptions!B21*B15+Assumptions!B22*B16+Assumptions!B17*B15
A19: Billed credits/doc = MAX(raw, 30 floor) | B19: =MAX(B18,Assumptions!B23)
A20: $ per document = billed credits × $/credit | B20: =B19*Assumptions!B5
A21: Total $ (Deep Extract, all docs) | B21: =B20*B17
A22: Note: with 3 pages/12 fields, raw = 16.2 cr but the 30-credit floor binds → Deep Extract is expensive for short docs.
